INFO;2020-10-25 22:21:04;fs_functions.py;fs_functions;122;Arquivo fs_functions.py presente na origem C:/Users/thipa/Desktop/workspaces/python-components/file_system
INFO;2020-10-25 22:21:04;fs_functions.py;fs_functions;122;Arquivo fs_functions.py presente na origem C:/Users/thipa/Desktop/workspaces/python-components/file_system
WARNING;2020-10-25 22:21:04;fs_functions.py;fs_functions;197;A última modificação do arquivo fs_functions.py (202010) não bate com o validador (202009)
INFO;2020-10-25 22:21:04;fs_functions.py;fs_functions;122;Arquivo fs_functions.py presente na origem C:/Users/thipa/Desktop/workspaces/python-components/file_system
INFO;2020-10-25 22:21:04;fs_functions.py;fs_functions;239;Cópia realizada com sucesso. Origem: C:/Users/thipa/Desktop/workspaces/python-components/file_system/fs_functions.py - Destino: C:/Users/thipa/Desktop/workspaces/python-components/testes/copia_fs_functions.py
DEBUG;2020-10-25 22:21:04;fs_functions.py;fs_functions;284;Iterando sobre os arquivos do diretório root
DEBUG;2020-10-25 22:21:04;fs_functions.py;fs_functions;298;Preenchendo variáveis de controle
DEBUG;2020-10-25 22:21:04;fs_functions.py;fs_functions;307;Salvando arquivo de controle gerado
ERROR;2020-10-25 22:21:04;fs_functions.py;fs_functions;315;Erro ao salvar arquivo de controle. Exception lançada: [WinError 3] O sistema não pode encontrar o caminho especificado: ''
INFO;2020-10-25 22:22:49;fs_functions.py;fs_functions;122;Arquivo fs_functions.py presente na origem C:/Users/thipa/Desktop/workspaces/python-components/file_system
INFO;2020-10-25 22:22:49;fs_functions.py;fs_functions;122;Arquivo fs_functions.py presente na origem C:/Users/thipa/Desktop/workspaces/python-components/file_system
WARNING;2020-10-25 22:22:49;fs_functions.py;fs_functions;197;A última modificação do arquivo fs_functions.py (202010) não bate com o validador (202009)
INFO;2020-10-25 22:22:49;fs_functions.py;fs_functions;122;Arquivo fs_functions.py presente na origem C:/Users/thipa/Desktop/workspaces/python-components/file_system
INFO;2020-10-25 22:22:49;fs_functions.py;fs_functions;239;Cópia realizada com sucesso. Origem: C:/Users/thipa/Desktop/workspaces/python-components/file_system/fs_functions.py - Destino: C:/Users/thipa/Desktop/workspaces/python-components/testes/copia_fs_functions.py
DEBUG;2020-10-25 22:22:49;fs_functions.py;fs_functions;284;Iterando sobre os arquivos do diretório root
DEBUG;2020-10-25 22:22:49;fs_functions.py;fs_functions;298;Preenchendo variáveis de controle
DEBUG;2020-10-25 22:22:49;fs_functions.py;fs_functions;307;Salvando arquivo de controle gerado
ERROR;2020-10-25 22:22:49;fs_functions.py;fs_functions;316;Erro ao salvar arquivo de controle. Exception lançada: [WinError 3] O sistema não pode encontrar o caminho especificado: ''
INFO;2020-10-25 22:26:26;fs_functions.py;fs_functions;122;Arquivo fs_functions.py presente na origem C:/Users/thipa/Desktop/workspaces/python-components/file_system
INFO;2020-10-25 22:26:26;fs_functions.py;fs_functions;122;Arquivo fs_functions.py presente na origem C:/Users/thipa/Desktop/workspaces/python-components/file_system
WARNING;2020-10-25 22:26:26;fs_functions.py;fs_functions;197;A última modificação do arquivo fs_functions.py (202010) não bate com o validador (202009)
INFO;2020-10-25 22:26:26;fs_functions.py;fs_functions;122;Arquivo fs_functions.py presente na origem C:/Users/thipa/Desktop/workspaces/python-components/file_system
INFO;2020-10-25 22:26:26;fs_functions.py;fs_functions;239;Cópia realizada com sucesso. Origem: C:/Users/thipa/Desktop/workspaces/python-components/file_system/fs_functions.py - Destino: C:/Users/thipa/Desktop/workspaces/python-components/testes/copia_fs_functions.py
DEBUG;2020-10-25 22:26:26;fs_functions.py;fs_functions;284;Iterando sobre os arquivos do diretório root
DEBUG;2020-10-25 22:26:26;fs_functions.py;fs_functions;299;Preenchendo variáveis de controle
DEBUG;2020-10-25 22:26:26;fs_functions.py;fs_functions;308;Salvando arquivo de controle gerado
ERROR;2020-10-25 22:26:26;fs_functions.py;fs_functions;317;Erro ao salvar arquivo de controle. Exception lançada: [WinError 3] O sistema não pode encontrar o caminho especificado: ''
INFO;2020-10-25 23:01:08;fs_functions.py;fs_functions;122;Arquivo fs_functions.py presente na origem C:/Users/thipa/Desktop/workspaces/python-components/file_system
INFO;2020-10-25 23:01:08;fs_functions.py;fs_functions;122;Arquivo fs_functions.py presente na origem C:/Users/thipa/Desktop/workspaces/python-components/file_system
WARNING;2020-10-25 23:01:08;fs_functions.py;fs_functions;197;A última modificação do arquivo fs_functions.py (202010) não bate com o validador (202009)
INFO;2020-10-25 23:01:08;fs_functions.py;fs_functions;122;Arquivo fs_functions.py presente na origem C:/Users/thipa/Desktop/workspaces/python-components/file_system
INFO;2020-10-25 23:01:08;fs_functions.py;fs_functions;239;Cópia realizada com sucesso. Origem: C:/Users/thipa/Desktop/workspaces/python-components/file_system/fs_functions.py - Destino: C:/Users/thipa/Desktop/workspaces/python-components/testes/copia_fs_functions.py
DEBUG;2020-10-25 23:01:08;fs_functions.py;fs_functions;284;Iterando sobre os arquivos do diretório root
DEBUG;2020-10-25 23:01:08;fs_functions.py;fs_functions;299;Preenchendo variáveis de controle
DEBUG;2020-10-25 23:01:08;fs_functions.py;fs_functions;308;Salvando arquivo de controle gerado
INFO;2020-10-25 23:01:41;fs_functions.py;fs_functions;122;Arquivo fs_functions.py presente na origem C:/Users/thipa/Desktop/workspaces/python-components/file_system
INFO;2020-10-25 23:01:41;fs_functions.py;fs_functions;122;Arquivo fs_functions.py presente na origem C:/Users/thipa/Desktop/workspaces/python-components/file_system
WARNING;2020-10-25 23:01:41;fs_functions.py;fs_functions;197;A última modificação do arquivo fs_functions.py (202010) não bate com o validador (202009)
INFO;2020-10-25 23:01:41;fs_functions.py;fs_functions;122;Arquivo fs_functions.py presente na origem C:/Users/thipa/Desktop/workspaces/python-components/file_system
INFO;2020-10-25 23:01:41;fs_functions.py;fs_functions;239;Cópia realizada com sucesso. Origem: C:/Users/thipa/Desktop/workspaces/python-components/file_system/fs_functions.py - Destino: C:/Users/thipa/Desktop/workspaces/python-components/testes/copia_fs_functions.py
DEBUG;2020-10-25 23:01:41;fs_functions.py;fs_functions;284;Iterando sobre os arquivos do diretório root
DEBUG;2020-10-25 23:01:41;fs_functions.py;fs_functions;299;Preenchendo variáveis de controle
DEBUG;2020-10-25 23:01:41;fs_functions.py;fs_functions;308;Salvando arquivo de controle gerado
INFO;2020-10-25 23:01:51;fs_functions.py;fs_functions;122;Arquivo fs_functions.py presente na origem C:/Users/thipa/Desktop/workspaces/python-components/file_system
INFO;2020-10-25 23:01:51;fs_functions.py;fs_functions;122;Arquivo fs_functions.py presente na origem C:/Users/thipa/Desktop/workspaces/python-components/file_system
WARNING;2020-10-25 23:01:51;fs_functions.py;fs_functions;197;A última modificação do arquivo fs_functions.py (202010) não bate com o validador (202009)
INFO;2020-10-25 23:01:51;fs_functions.py;fs_functions;122;Arquivo fs_functions.py presente na origem C:/Users/thipa/Desktop/workspaces/python-components/file_system
INFO;2020-10-25 23:01:51;fs_functions.py;fs_functions;239;Cópia realizada com sucesso. Origem: C:/Users/thipa/Desktop/workspaces/python-components/file_system/fs_functions.py - Destino: C:/Users/thipa/Desktop/workspaces/python-components/testes/copia_fs_functions.py
DEBUG;2020-10-25 23:01:51;fs_functions.py;fs_functions;284;Iterando sobre os arquivos do diretório root
DEBUG;2020-10-25 23:01:51;fs_functions.py;fs_functions;299;Preenchendo variáveis de controle
DEBUG;2020-10-25 23:01:51;fs_functions.py;fs_functions;308;Salvando arquivo de controle gerado
ERROR;2020-10-25 23:01:51;fs_functions.py;fs_functions;316;Erro ao salvar arquivo de controle. Exception lançada: No module named 'openpyxl'
INFO;2020-10-25 23:02:02;fs_functions.py;fs_functions;122;Arquivo fs_functions.py presente na origem C:/Users/thipa/Desktop/workspaces/python-components/file_system
INFO;2020-10-25 23:02:02;fs_functions.py;fs_functions;122;Arquivo fs_functions.py presente na origem C:/Users/thipa/Desktop/workspaces/python-components/file_system
WARNING;2020-10-25 23:02:02;fs_functions.py;fs_functions;197;A última modificação do arquivo fs_functions.py (202010) não bate com o validador (202009)
INFO;2020-10-25 23:02:02;fs_functions.py;fs_functions;122;Arquivo fs_functions.py presente na origem C:/Users/thipa/Desktop/workspaces/python-components/file_system
INFO;2020-10-25 23:02:02;fs_functions.py;fs_functions;239;Cópia realizada com sucesso. Origem: C:/Users/thipa/Desktop/workspaces/python-components/file_system/fs_functions.py - Destino: C:/Users/thipa/Desktop/workspaces/python-components/testes/copia_fs_functions.py
DEBUG;2020-10-25 23:02:02;fs_functions.py;fs_functions;284;Iterando sobre os arquivos do diretório root
DEBUG;2020-10-25 23:02:02;fs_functions.py;fs_functions;299;Preenchendo variáveis de controle
DEBUG;2020-10-25 23:02:02;fs_functions.py;fs_functions;308;Salvando arquivo de controle gerado
INFO;2020-10-25 23:02:43;fs_functions.py;fs_functions;122;Arquivo fs_functions.py presente na origem C:/Users/thipa/Desktop/workspaces/python-components/file_system
INFO;2020-10-25 23:02:43;fs_functions.py;fs_functions;122;Arquivo fs_functions.py presente na origem C:/Users/thipa/Desktop/workspaces/python-components/file_system
WARNING;2020-10-25 23:02:44;fs_functions.py;fs_functions;197;A última modificação do arquivo fs_functions.py (202010) não bate com o validador (202009)
INFO;2020-10-25 23:02:44;fs_functions.py;fs_functions;122;Arquivo fs_functions.py presente na origem C:/Users/thipa/Desktop/workspaces/python-components/file_system
INFO;2020-10-25 23:02:44;fs_functions.py;fs_functions;239;Cópia realizada com sucesso. Origem: C:/Users/thipa/Desktop/workspaces/python-components/file_system/fs_functions.py - Destino: C:/Users/thipa/Desktop/workspaces/python-components/testes/copia_fs_functions.py
DEBUG;2020-10-25 23:02:44;fs_functions.py;fs_functions;284;Iterando sobre os arquivos do diretório root
DEBUG;2020-10-25 23:02:44;fs_functions.py;fs_functions;299;Preenchendo variáveis de controle
DEBUG;2020-10-25 23:02:44;fs_functions.py;fs_functions;308;Salvando arquivo de controle gerado
